Workbook

Sheet Indice
A1: ÍNDICE — Libro unificado (3 archivos de origen)
A3: Hoja | B3: Archivo de origen | C3: Filas | D3: Columnas
A4: Corpus_corregido | B4: Corpus_unificado_revision_motivacion_ABR.xlsx | C4: 164 | D4: 58
A5: Marcas_declaradas | B5: Corpus_unificado_revision_motivacion_ABR.xlsx | C5: 166 | D5: 29
A6: Marcas_todas | B6: Corpus_unificado_revision_motivacion_ABR.xlsx | C6: 166 | D6: 29
A7: Resumen_comparado | B7: Corpus_unificado_revision_motivacion_ABR.xlsx | C7: 62 | D7: 8
A8: Cambios_aplicados | B8: Corpus_unificado_revision_motivacion_ABR.xlsx | C8: 156 | D8: 5
A9: Diccionario_causales | B9: Corpus_unificado_revision_motivacion_ABR.xlsx | C9: 27 | D9: 5
A10: Leyenda_estatus | B10: Corpus_unificado_revision_motivacion_ABR.xlsx | C10: 9 | D10: 3
A11: Trazabilidad_fusion | B11: Corpus_unificado_revision_motivacion_ABR.xlsx | C11: 89 | D11: 6
A12: Criterios_y_fuentes | B12: Corpus_unificado_revision_motivacion_ABR.xlsx | C12: 40 | D12: 1
A13: Revision_motivacion_163 | B13: Corpus_unificado_revision_motivacion_ABR.xlsx | C13: 172 | D13: 10
A14: Llamoja_17_ABR18 | B14: Corpus_unificado_revision_motivacion_ABR.xlsx | C14: 26 | D14: 11
A15: Tipologia_Llamoja | B15: corpus_tipologia_llamoja_NULA__CONO.xlsx | C15: 42 | D15: 10
... A17: Sumarisimo_Llamoja | B17: Sumarisimo_Llamoja_17expedientes_SUM.xlsx | C17: 18 | D17: 5

Sheet Corpus_corregido
A1: N° | B1: Clave expediente | C1: Expediente (código de origen) | D1: Corpus / grupo | E1: Materia | F1: Sala | G1: Sentencia de vista | H1: Resolución | I1: Fecha SV | J1: Año SV | K1: Juez A quo | L1: Juez superior ponente | M1: Sentido del fallo / resultado del control | N1: Defectos declarados (ratio) | O1: Registros totales (todo estatus) | P1: D01 Notificación o emplazamiento defectuoso | Q1: D02 Vulneración del derecho de defensa | R1: D03 Litisconsorte necesario omitido | S1: D04 Declaración indebida de rebeldía | T1: D05 Omisión o irregularidad de audiencia | U1: D06 Deficiente fijación de puntos/hechos controvertidos | V1: D07 Prueba admitida y no actuada | W1: D08 Indebida admisión o exclusión de prueba | X1: D09 Prueba de oficio irregular | Y1: D10 Falta de contradictorio de la prueba | Z1: D11 Omisión de valoración de prueba decisiva | AA1: D12 Valoración probatoria defectuosa | AB1: D13 Motivación insuficiente | AC1: D14 Motivación aparente | AD1: D15 Falta o defecto interno de motivación | AE1: D16 Incongruencia procesal | AF1: D17 Falta de respuesta a agravios | AG1: D18 Violación de preclusión procesal | AH1: D19 Omisión de resolver incidencia previa | AI1: D20 Otro defecto insubsanable del procedimiento | AJ1: D21 Deficiencia de motivación externa (justificación de las premisas) | AK1: D22 Nulidad refleja, concatenada o por hecho sobreviniente | AL1: D23 Motivación defectuosa sin especificación del supuesto | AM1: Insubsanabilidad declarada | AN1: Nulidad sin vicio procesal identificado | AO1: Verificación pendiente de cita | AP1: Cambios aplicados | AQ1: Tipo de motivación (Llamoja) — principal | AR1: Tipo de motivación — secundario | AS1: ¿La Sala etiqueta el supuesto Llamoja? | AT1: Cita textual 1 | AU1: Cita 1 — qué sustenta | AV1: Cita textual 2 | AW1: Cita 2 — qué sustenta | AX1: Cita textual 3 | AY1: Cita 3 — qué sustenta | AZ1: Observaciones | BA1: Archivo / fuente documental | BB1: Fuentes del registro | BC1: N° de fuentes | BD1: DESC_PROCESO | BE1: TIPO_FALLO (NULA/REVOCADA/CONFIRMADA) | BF1: PROCESO_TIPO
A2: 1 | B2: 00001-2018 | C2: 00001-2018-0-0401-JR-CI-10 | D2: Matriz sumarísimos — anteriores a 2019 | E2: Otorgamiento de escritura pública | F2: 2SC | G2: SV 343-2019-2SC | H2: Res. 25 (tres-2SC) | I2: 09/07/2019 | J2: 2019 | K2: Javier Marín Andia | M2: NULA (reenvío) | N2: 2 | O2: 2 | AA2: DECLARADO — «se aprecia que el juez de la causa ha incurrido en error al considerar que el inmueble respecto del cual se pretende se otorgue una escritura pública es ganancial, fundamento que ha servido para declarar improcedente la demanda» | AD2: DECLARADO — «la resolución apelada contiene una motivación interna defectuosa o una falta de motivación interna del razonamiento conforme a lo señalado por el Tribunal Constitucional en el EXP. N° 00728-2008-PHC/TC» | AZ2: El A quo tuvo por ganancial el bien pese a que la partida de matrimonio de f. 33 (prueba de oficio admitida por él mismo) acreditaba que la venta fue anterior al matrimonio. | BB2: Matriz_defectos_procesales_1ra_SV | BC2: 1 | BD2: SUMARISIMO | BE2: NULA | BF2: SN
A3: 2 | B3: 00072-2023 | C3: 00072-2023-0-0401-JR-CI-06 | D3: Matriz sumarísimos — grupo 2024 | E3: Desalojo por ocupación precaria | F3: 2SC | G3: SV 429-2025-2SC | H3: Res. 43 (ocho-2SC) | I3: 10/09/2025 | J3: 2025 | K3: Patricia Valdivia Franco | M3: NULA DE OFICIO (reenvío) | N3: 4 | O3: 4 | Z3: DECLARADO — «solamente se analiza la inspección judicial y no medios probatorios directos que acrediten el lazo consanguíneo y/o afinidad que existiría entre las demandadas y Zhaodi Dara Bravo Salas, Josué Daniel Arenas Salas y Edmundo Ciro Barrantes» | AD3: DECLARADO — «la sentencia impugnada adolece de vicios de motivación en su fase interna y externa, al no deducirse de las premisas fácticas y de los medios probatorios aportados, la conclusión que los litisconsortes necesarios pasivos ostentan también legitimidad para poseer» | AE3: DECLARADO — «se omitió pronunciamiento en relación a la buena fe del tercero adquiriente y de la transferencia del predio a favor de Juan Manuel Salazar Herrera y Epifanía Rosenda Barrantes Quispe» | AJ3: DECLARADO — «la sentencia impugnada adolece de vicios de motivación en su fase interna y externa» (extremo externo: justificación de las premisas) | AM3: Sí | AP3: Baja D20→— · Alta —→D21 | AZ3: Nulidad declarada de oficio (art. 176 in fine CPC) pese a que el apelante pedía revocatoria. | BB3: Matriz_defectos_procesales_1ra_SV | BC3: 1 | BD3: SUMARISIMO | BE3: NULA | BF3: SN
A4: 3 | B4: 00115-2012 | C4: 00115-2012-0-0401-JR-CI-08 | D4: Matriz sumarísimos — anteriores a 2019 | E4: Desalojo por ocupación precaria | F4: 2SC | G4: SV 660-2018-2SC | H4: Res. 63 (siete-2SC) | I4: 21/12/2018 | J4: 2018 | K4: Omar del Carpio Medina | M4: NULA (reenvío) | N4: 1 | O4: 2 | P4: DECLARADO — «el Juzgado no ha notificado con la demanda y anexos en el predio a desalojar, inobservando dicha normatividad al expedir la sentencia» | Q4: DERIVADO — «ello a efecto de garantizar el conocimiento de la existencia del proceso a los ocupantes del predio»; «por haberse transgredido el principio al debido proceso consagrado por el artículo 139 inciso 3) de la Constitución Política del Estado» | AM4: Sí | AP4: Baja D20→— · Reclasificación de estatus D02→D02 (derivado) | AZ4: Art. 589 CPC: en desalojo la demanda debe notificarse además en el predio. La Sala precisa que el apersonamiento de un codemandado «no convalida ni subsana dicha omisión». | BB4: Matriz_defectos_procesales_1ra_SV | BC4: 1 | BD4: SUMARISIMO | BE4: NULA | BF4: SN
A5: 4 | B5: 00129-2022 | C5: 00129-2022-0-0401-JR-CI-01 | D5: Matriz sumarísimos — grupo 2024 | E5: Desalojo por ocupación precaria | F5: 2SC | G5: SV 563-2024-2SC | H5: Res. 47 (cinco-2SC) | I5: 10/12/2024 | J5: 2024 | K5: Shelah Galagarza Pérez | M5: REVOCADA → IMPROCEDENTE | N5: 0 | O5: 0 | AZ5: Sin vicio procesal declarado. Pronunciamiento inhibitorio por concurrencia de dos títulos de propiedad (ff. 21 y 58, IV Pleno Casatorio). | BB5: Matriz_defectos_procesales_1ra_SV | BC5: 1 | BD5: SUMARISIMO | BE5: REVOCADA | BF5: SR
A6: 5 | B6: 00132-2015 | C6: 00132-2015 | D6: Pre-2019 | F6: 2SC | G6: SV N° 667-2018-2SC | I6: 27/12/2018 | J6: 2018 | M6: Revocada | N6: 0 | O6: 0 | BB6: Comparativa_defectos_2018_vs_2024 + Defectos_procesales_SV_CSJA | BC6: 2 | BD6: CONOCIMIENTO | BE6: REVOCADA | BF6: CR
A7: 6 | B7: 00153-2022 | C7: 00153-2022-0-0401-SP-CI-03 | D7: Matriz sumarísimos — grupo 2024 | E7: Revisión judicial de procedimiento de ejecución coactiva | F7: 3SC | G7: SV 51-2025-3SC | H7: Res. 20 (dos) | I7: 31/01/2025 | J7: 2025 | K7: Javier Talavera Ugarte | M7: REVOCADA → INFUNDADA | N7: 0 | O7: 0 | AZ7: Sin vicio procesal declarado en el proceso judicial. La revocatoria se funda en error en la aplicación del régimen de notificación electrónica (art. 20.4 TUO LPAG y 6ª DCF del D. Leg. 1511). | BB7: Matriz_defectos_procesales_1ra_SV | BC7: 1 | BD7: SUMARISIMO | BE7: REVOCADA | BF7: SR
A8: 7 | B8: 00192-2021 | C8: 00192-2021 | D8: 2024 | G8: SV N° 285-2026 | I8: 04/06/2026 | J8: 2026 | M8: Revocada | N8: 0 | O8: 0 | BB8: Comparativa_defectos_2018_vs_2024 + Defectos_procesales_SV_CSJA | BC8: 2 | BD8: CONOCIMIENTO | BE8: REVOCADA | BF8: CR
A9: 8 | B9: 00234-2018 | C9: 00234-2018-0-0401-JR-JC-03 | D9: Matriz sumarísimos — anteriores a 2019 | E9: Desalojo por ocupación precaria | F9: 3SC | G9: SV 638-2019-3SC | H9: Res. 25 (seis) | I9: 23/08/2019 | J9: 2019 | K9: Zoilo Chávez Mamani | M9: REVOCADA → INFUNDADA | N9: 0 | O9: 1 | AH9: ALEGADO — «Debe declararse la nulidad de la sentencia puesto que ha sido emitida sin que las resoluciones tres y catorce hayan quedado consentidas» | AP9: Migración D20→D19 | AZ9: La Sala desestima la nulidad alegada (art. 190 in fine CPC) y revoca por el fondo: falta de comunicación indubitable de fenecimiento del comodato (IV Pleno). | BB9: Matriz_defectos_procesales_1ra_SV | BC9: 1 | BD9: SUMARISIMO | BE9: REVOCADA | BF9: SR
A10: 9 | B10: 00320-2023 | C10: 00320-2023 | D10: 2024 | F10: 2SC | G10: SV N° 398-2025-2SC | I10: 26/08/2025 | J10: 2025 | M10: Nula | N10: 1 | O10: 1 | AB10: DECLARADO — “…contractual. En ese sentido, la sentencia materia de alzada adolece de motivación insuficiente “[…] referida básicamente al mínimo de motivación exigible atendiendo a las razones de hecho o de derecho indispensables para asumir que la decisión está debidamente motivada. Si bien, como ha establecido este Tribunal, no se trata de dar…” | BB10: Comparativa_defectos_2018_vs_2024 + Defectos_procesales_SV_CSJA | BC10: 2 | BD10: CONOCIMIENTO | BE10: NULA | BF10: CN
A11: 10 | B11: 00340-2002 | C11: 00340-2002 | D11: Pre-2019 | F11: 2SC | G11: SV N° 0008-2018-2SC | I11: 08/01/2018 | J11: 2018 | M11: Nula | N11: 2 | O11: 2 | Q11: DECLARADO — “…de acto jurídico se encuentra incursa además en la causal prevista por el inciso 8) del artículo 219 del Código Civil", vulnera el derecho de defensa de las partes, porque la contestación de la demanda, no se alegó la causal invocada de oficio por el señor juez; no habiéndose ofrecido, ni actuado pruebas sobre la causal formulada por el juez. c) En el décimo pr…” | AE11: DECLARADO — “…Se ha sentenciado sobre una causal no determinada como punto controvertido materia de Probanza o thema decidendum, acarreando un estado de indefensión a las partes del proceso, pues el hecho que el A quo, comunique a las partes mediante resolución Nro. 2…” | AP11: Migración D06→D16 · Baja D15→— · Sustitución de cita D16→D16 | BB11: Comparativa_defectos_2018_vs_2024 + Defectos_procesales_SV_CSJA | BC11: 2 | BD11: CONOCIMIENTO | BE11: NULA | BF11: CN
A12: 11 | B12: 00367-2024 | C12: 00367-2024-0-0401-JR-CI-10 | D12: Matriz sumarísimos — grupo 2024 | E12: Desalojo por ocupación precaria | F12: 1SC | G12: SV 338-2024-1SC | H12: Res. 12 (tres-1SC) | I12: 22/07/2024 | J12: 2024 | K12: Zoraida Julia Salas Flores | M12: REVOCADA → INFUNDADA | N12: 0 | O12: 0 | AZ12: Sin vicio procesal declarado respecto de la sentencia apelada. La Sala observa un error de juzgamiento en un proceso anterior (Exp. 1999-0488) ajeno a esta causa. | BB12: Matriz_defectos_procesales_1ra_SV | BC12: 1 | BD12: SUMARISIMO | BE12: REVOCADA | BF12: SR
A13: 12 | B13: 00414-2023 | C13: 00414-2023-0-0401-JR-CI-02 | D13: Llamoja — SV de control (2021-2023) | E13: Enriquecimiento sin causa / indemnización | F13: 3SC | G13: 178-2025-3SC | H13: 18 | I13: dos mil veinticinco, Mayo veintiuno | J13: 2025 | L13: Burga Cervantes | M13: NULA | N13: 2 | O13: 2 | AB13: DECLARADO — (evidencia en las columnas «Cita textual 1–3» de esta misma fila) | AE13: DECLARADO — (evidencia en las columnas «Cita textual 1–3» de esta misma fila) | AQ13: d) Motivación insuficiente | AR13: e) Motivación sustancialmente incongruente | AS13: No | AT13: «El juez no ha motivado su resolución, por lo que esta adolece de debida motivación, por no haberse pronunciado sobre todos los hechos controvertidos y justificar objetivamente las razones de su decisión.» | AU13: d)/e): no se pronuncia sobre todos los hechos controvertidos | AV13: «En consecuencia, la sentencia apelada no se encuentra conforme a derecho y debe ser declarada nula, para que el juzgado A quo emita pronunciamiento de fondo sobre la pretensión incoada por la parte demandante.» | AW13: Efecto: nulidad y pronunciamiento de fondo | AZ13: 'No haberse pronunciado sobre todos los hechos controvertidos y justificar objetivamente las razones'. Improcedencia declarada en sentencia; ordena pronunciamiento de fondo. | BA13: 414 2023 SV.doc | BB13: Clasificacion_SV_ABR24_Llamoja_defectos | BC13: 1 | BD13: ABREVIADO | BE13: NULA | BF13: AN
A14: 13 | B14: 00428-2017 | C14: 00428-2017-0-0401-JP-CI-02 | D14: Matriz sumarísimos — anteriores a 2019 | E14: Desalojo por ocupación precaria | F14: 2SC | G14: SV 033-2020-2SC | H14: Res. 23 (cinco-2SC) | I14: 17/01/2020 | J14: 2020 | K14: Carlos Polanco Gutiérrez | M14: REVOCADA → FUNDADA | N14: 0 | O14: 2 | AB14: ADVERTIDO — «el juez tampoco ha cumplido con exponer razones o motivos propios por los cuales considera que en el caso en concreto se debe considerar el vínculo familiar de conviviente como título para poseer» | AJ14: ADVERTIDO — «lo que evidencia que la sentencia tiene una motivación defectuosa, lo cual afecta la validez la recurrida ya que se ha vulnerado el derecho del demandante a una resolución debidamente motivada» | AP14: Migración D15→D21 · Reclasificación de estatus —→ADV | AZ14: Uso de casaciones sobre supuestos fácticos distintos («su aplicación en autos es equivocada ya que no se tratan de supuestos similares»). Pese al vicio, la Sala revoca y falla el fondo (rebeldía de la demandada). | BB14: Matriz_defectos_procesales_1ra_SV | BC14: 1 | BD14: SUMARISIMO | BE14: REVOCADA | BF14: SR
A15: 14 | B15: 00598-2022 | C15: 00598-2022 | D15: 2024 | F15: 3SC | G15: SV N° 256-2025-3SC | I15: 20/06/2025 | J15: 2025 | M15: Nula | N15: 2 | O15: 2 | AA15: DECLARADO — “…denotarían la supuesta existencia de irregularidades en la partida de nacimiento de la demandante, de carácter formal, no habiendo valorado el contexto en el que se expide la partida de nacimiento y otras que han sido desarrolladas en la presente resolución; por lo que corresponde declarar nula la sentencia venida en grado, disponiendo que el Juez de origen emita un nuevo p…” | AB15: DECLARADO — “…vierte que el Juez de primera instancia no ha realizado un análisis suficiente de lo actuado en autos, habiéndose centrado en las cuestiones que denotarían la supuesta existencia de irregularidades en la partida de nacimiento de la demandante, de carácter formal, no habiendo valorado el contexto en e…” | BB15: Comparativa_defectos_2018_vs_2024 + Defectos_procesales_SV_CSJA | BC15: 2 | BD15: CONOCIMIENTO | BE15: NULA | BF15: CN
A16: 15 | B16: 00646-2024 | C16: 00646-2024-0-0401-JR-CI-01 | D16: Matriz sumarísimos — grupo 2024 | E16: Desalojo por ocupación precaria | F16: 2SC | G16: SV 240-2025-2SC | H16: Res. 21 (tres-2SC) | I16: 23/05/2025 | J16: 2025 | K16: Shelah Galagarza Pérez | M16: NULA (reenvío) | N16: 3 | O16: 3 | AA16: DECLARADO — «No ha tomado en cuenta que, a la parte demandada le corresponde desvirtuar la condición de precario que se le imputa, todo ello en virtud del principio de reversión de la carga de la prueba, contemplada por el artículo 196 del Código Procesal Civil» | AE16: DECLARADO — «si bien el A quo se ha pronunciado sobre la codemandada Ana María Meneses Portugal; sin embargo, ha omitido pronunciarse sobre la condición de poseedores precarios que se imputa a los codemandados Walter Cisneros Meneses, Dalia Cisneros Meneses» | AL16: DECLARADO — «se tiene que se ha vulnerado el inciso 5º del artículo 139 de nuestra constitución» | AP16: Baja D11→— · Migración D13→D23 | AZ16: Incongruencia omisiva respecto de dos codemandados declarados rebeldes e inversión indebida de la carga de la prueba. | BB16: Matriz_defectos_procesales_1ra_SV | BC16: 1 | BD16: SUMARISIMO | BE16: NULA | BF16: SN
A17: 16 | B17: 00661-2023 | C17: 00661-2023-0-0401-JP-CI-06 | D17: Matriz sumarísimos — grupo 2024 | E17: Obligación de dar suma de dinero | F17: 2SC | G17: SV 302-2025-2SC | H17: Res. 18 (cuatro-2SC) | I17: 27/06/2025 | J17: 2025 | K17: Edgard Pineda Gamarra | M17: NULA (reenvío) | N17: 2 | O17: 2 | AA17: DECLARADO — «se evidencia que el juzgador no ha efectuado una debida valoración de los medios probatorios y actuados obrantes en el caso de autos» | AB17: DECLARADO — «incurriéndose en vicio procesal por motivación insuficiente para la dilucidación de los hechos materia de litis» | AP17: Baja D11→— | AZ17: La rebeldía (art. 461 CPC) no exime del análisis; la Sala recuerda la facultad de prueba de oficio (art. 194 CPC). | BB17: Matriz_defectos_procesales_1ra_SV | BC17: 1 | BD17: SUMARISIMO | BE17: NULA | BF17: SN
A18: 17 | B18: 00742-2022 | C18: 00742-2022 | D18: 2024 | G18: SV N° 196-2025 | I18: 16/05/2025 | J18: 2025 | M18: Otro | N18: 4 | O18: 4 | Q18: DECLARADO — “…ste proceder habría resultado legítimo en la medida de que, el juez de primera instancia hubiese promovido un debido contradictorio respecto de esta causal de nulidad de acto jurídico no invocada. Una forma de verificar que no se promovió el contradictorio respecto de esta causal de nulidad, es analizar los pu…” | S18: DECLARADO — “…udible no resaltar que en la página quince de la sentencia, el juez ha incurrido en un gravísimo error al aceptar como ciertos los argumentos expuestos en la contestación del demandado Andrés Saya Alarcón, que en la presente causa ostenta la posición de rebelde y la cual fue expresamente declarada improcedente en la resolución N.° 7 del mismo despacho. Este h…” | Z18: DECLARADO — “…La falta de valoración de pruebas clave que demuestran la titularidad de William Canazas Carta genera un claro desbalance en el proceso, al ignorar evidencias que podrían haber conducido a un resultado judicial diferente. p) La jurisprudencia establece que el…” | AE18: DECLARADO — “…urídico no invocada. Una forma de verificar que no se promovió el contradictorio respecto de esta causal de nulidad, es analizar los puntos controvertidos (fojas cuatrocientos setenta y seis), en donde se advierte que ninguno de estos plantea la controversia de la causal de imposibilidad jurídica por el objeto. Es evidente que haber omitido establecer esta causal (imposib…” | AP18: Migración D10→D02 · Migración D06→D16 · Sustitución de cita D16→D16 | BB18: Comparativa_defectos_2018_vs_2024 + Defectos_procesales_SV_CSJA | BC18: 2 | BD18: CONOCIMIENTO | BE18: OTRO | BF18: CO
A19: 18 | B19: 00748-2013 | C19: 00748-2013 | D19: Pre-2019 | F19: 2SC | G19: SV N° 674-2018-2SC | I19: 28/12/2018 | J19: 2018 | M19: Nula | N19: 1 | O19: 1 | AD19: DECLARADO — “…azonamiento conforme al Tribunal Constitucional. En conclusión, en mérito a lo expuesto precedentemente se concluye que la sentencia recurrida no se encuentra debidamente motivada contraviniendo de esta manera no sólo lo establecido en el inciso 3) del artículo 122 del Código Procesal Civil, sino también lo dispuesto en el inciso 5) del artículo 139 de nuestra Constitución Política, por lo que co…” | AO19: Cita truncada al inicio: verificar en el original si el Colegiado califica el vicio como falta de motivación interna o emplea una fórmula genérica. | BB19: Comparativa_defectos_2018_vs_2024 + Defectos_procesales_SV_CSJA | BC19: 2 | BD19: CONOCIMIENTO | BE19: NULA | BF19: CN
A20: 19 | B20: 00760-2021 | C20: 00760-2021-0-0401-JP-CI-07 | D20: Llamoja — SV de control (2021-2023) | E20: Obligación de dar suma de dinero | F20: 3SC | G20: 34-2025-3SC | H20: 31 | I20: dos mil veinticinco, Enero veintinueve | J20: 2025 | L20: Marroquín Mogrovejo | M20: NULA | N20: 2 | O20: 2 | W20: DECLARADO — (evidencia en las columnas «Cita textual 1–3» de esta misma fila) | Y20: DECLARADO — (evidencia en las columnas «Cita textual 1–3» de esta misma fila) | AQ20: — Sin vicio de motivación como causal | AS20: No | AT20: «Así las cosas, tenemos que la decisión se ha emitido sin que el juez de la causa haya garantizado el derecho de las partes de propiciar y conducir el debate de manera previa a su decisión, vulnerando de ese modo su derecho al contradictorio, al sustentar la decisión en la valoración sorpresiva de pruebas no admitidas en el proceso y sobre las que ambas partes, no se permitió que ejerzan el derecho que corresponda en forma previa a su valoración y posterior decisión; por tanto, se ha incurrido en nulidad que debe ser declarada por esta sala al haber resuelto sin tener en cuenta el mérito de lo actuado conforme exige el inciso 3 del artículo 122° del Código Procesal Civil.» | AU20: Falta de contradictorio: valoración sorpresiva de prueba no admitida | AV20: «Por otro lado, si los documentos mencionados tiene relevancia e incidencia determinante en la litis, en todo caso, el juez de la causa debió, en forma previa a emitir sentencia, ejercer la facultad prevista en el artículo 194° del Código Procesal Civil “…que confiere al juez un poder probatorio con carácter de facultad excepcional … esta disposición legal habilita al juez a realizar prueba de oficio, cuando el caso así lo amerite, respetando los límites impuestos por el legislador” como lo establece la casación número 1242-2017 Lima Este; lo que no hizo y que debe evaluar el juez de primera instancia.» | AW20: Prueba de oficio no ejercida (art. 194 CPC; Cas. 1242-2017) | AZ20: Valoración sorpresiva de pruebas no admitidas, sin contradictorio (art. 122.3 CPC). El agravio habla de 'indebida motivación', pero la Sala anula por vicio probatorio-procesal. | BA20: 760 2021 SV 2025.doc | BB20: Clasificacion_SV_ABR24_Llamoja_defectos | BC20: 1 | BD20: ABREVIADO | BE20: NULA | BF20: AN
A21: 20 | B21: 00774-2021 | C21: 00774-2021-0-0401-JR-CI-05 | D21: Llamoja — SV de control (2021-2023) | E21: División y partición | F21: 2SC | G21: 161-2025-2SC | H21: 28 | I21: dos mil veinticinco, Abril catorce | J21: 2025 | L21: Yucra Quispe | M21: NULA | N21: 2 | O21: 2 | AE21: DECLARADO — (evidencia en las columnas «Cita textual 1–3» de esta misma fila) | AJ21: DECLARADO — (evidencia en las columnas «Cita textual 1–3» de esta misma fila) | AP21: Migración D20→D21 | AQ21: c) Deficiencia de motivación externa | AS21: No | AT21: «Conforme a lo señalado, al haberse emitido la sentencia, sin tener en cuenta lo señalado en el punto anterior, se ha vulnerado el derecho a la tutela jurisdiccional prevista en el inciso 3 del artículo 139 de nuestra constitución, por lo que al amparo de lo establecido en el artículo 176 , concordante con el 171 del Código Procesal Civil debe anularse la apelada.» | AU21: c) Premisa no confrontada con los hechos de la demanda (139.3) | AV21: «De la revisión de los actuados, se tiene que, el juzgador al emitir la apelada: a) No ha tomado en cuenta que, tratándose de la pretensión de división y partición, los hechos que se invoquen deben estar referidos a: 1) La existencia de un estado de copropiedad sobre un bien; 2) Que el bien no haya sido objeto de división y partición; 3) Que los copropietarios sean titulares de derechos sobre el bien; b) No ha tomado en cuenta que, la causal de improcedencia de la demanda de falta de conexión lógica entre los hechos y el petitorio prevista en el inciso 4° del artículo 427 del Código procesal Civil, se da cuando se advierte la evidente incongruencia entre lo que se solicita(pide) en el petitorio de la pretensión demandada y los fundamentos de hecho que sustentan dicha pretensión, es decir que los hechos que se invoca no están referidos a los supuestos de procedencia objeto del proceso; c) No ha tomado en cuenta que, cuando se formula una pretensión en el escrito de demanda, los hechos que se invoquen como sustento del petitorio, deben estar referidos necesariamente a los supuesto de procedencia de la institución jurídica material que se invoca en el petitorio de la demanda; d) No ha tomado en cuenta que, en el escrito de demanda de fojas dieciséis al veinte, subsanada a fojas cuarenta y cuatro al cuarenta y seis, se advierte que Pedro Isaias Pertalta Vilca, ha interpuesto la pretensión de división y participación del bien inmueble ubicado en el Pueblo Joven La Tomilla Manzana N, Lote 25, Zona A del distrito de Cayma, provincia y departamento de Arequipa, debidamente inscrito en la Partida registral del Predio número P06003392 del registro de Predios de los registros Públicos de Arequipa; en cuyos fundamentos facticos, ha invocado la existencia de un estado de copropiedad del bien objeto de litis, entre el demandante y los demandados Genaro Mercedes Peralta Vilca, Raymunda Emperatriz Peralta Vilca y Jesús Avelino Peralta Vilca y ha señalado los porcentajes que corresponderían a cada uno de los copropietarios; los que están referidos a los supuestos de procedencia de la pretensión de división y partición, ya que, los hechos invocado en la demanda están referidos a la existencia de un estado de copropiedad sobre el bien objeto de litis, que el bien no ha sido objeto de división y partición, y que los copropietarios demandante y demandados son titulares de derechos sobre el bien inmueble ubicado en el Pueblo Joven La Tomilla Manzana N, Lote 25, Zona A del distrito de Cayma, provincia y departamento de Arequipa, debidamente inscrito en la Partida registral del Predio número P06003392.» | AW21: Concepto de incongruencia aplicado al art. 427.4 CPC | AZ21: Improcedencia (art. 427.4) sin confrontar los hechos de la demanda que sí describen copropiedad. La Sala invoca 139.3 (tutela) y no etiqueta vicio de motivación. c) tentativo. | BA21: 774 2021 SV 2025.doc | BB21: Clasificacion_SV_ABR24_Llamoja_defectos | BC21: 1 | BD21: ABREVIADO | BE21: NULA | BF21: AN
A22: 21 | B22: 00788-2013 | C22: 00788-2013 | D22: Pre-2019 | F22: 2SC | G22: SV N° 191-2021-2SC | I22: 01/03/2021 | J22: 2021 | M22: Nula | N22: 1 | O22: 1 | AE22: DECLARADO — “…es decir, emitió un pronunciamiento distinto a lo alegado por la parte demandante y a las fijadas en los puntos controvertidos, lo que evidencia que en el caso subjúdice el A quo ha emitido una sentencia extra petita, amparándose para ello en el principio del iura novit curia. Empero, si bien el juzgador ha aplicado el principio del i…” | AP22: Baja D06→— | BB22: Comparativa_defectos_2018_vs_2024 + Defectos_procesales_SV_CSJA | BC22: 2 | BD22: CONOCIMIENTO | BE22: NULA | BF22: CN
A23: 22 | B23: 00848-2011 | C23: 00848-2011-0-0411-JR-CI-08 | D23: Matriz sumarísimos — anteriores a 2019 | E23: Otorgamiento de escritura pública | F23: 3SC | G23: SV 309-2019-3SC | H23: Res. 58 (cuatro) | I23: 27/05/2019 | J23: 2019 | K23: Ronald Valencia de Romaña | M23: REVOCADA → FUNDADA EN PARTE | N23: 0 | O23: 1 | AA23: ADVERTIDO — «el Juez a quo no ha realizado una valoración conjunta, razonada y adecuada de los medos probatorios aportados al proceso; al documento de compraventa del siete de octubre de mil novecientos ochenta y dos… no se le ha asignado el valor probatorio sobre la real intención de las partes» | AP23: Migración D11→D12 | AZ23: La Sala invoca expresamente la Circular sobre reenvío (RA N° 002-2014-CE-PJ) y opta por corregir en instancia en lugar de anular. | BB23: Matriz_defectos_procesales_1ra_SV | BC23: 1 | BD23: SUMARISIMO | BE23: REVOCADA | BF23: SR
A24: 23 | B24: 00856-2017 | C24: 00856-2017 | D24: Pre-2019 | F24: 1SC | G24: SV N° 525-2019-1SC | I24: 01/08/2019 | J24: 2019 | M24: Nula e insubsistente | N24: 1 | O24: 1 | AE24: DECLARADO — “…se ha incurrido en causal de nulidad por falta de motivación de una pretensión accesoria, y corresponderá al juez emitir nuevo pronunciamiento tomando en cuenta la doctrina Jurisprudencial vinculante emitida en el IV Pleno Casatorio Civil, Casación N° 2195-2011-UCAYALI, en el entendido d…” | AP24: Migración D15→D16 | BB24: Comparativa_defectos_2018_vs_2024 + Defectos_procesales_SV_CSJA | BC24: 2 | BD24: CONOCIMIENTO | BE24: NULA | BF24: CN
A25: 24 | B25: 00879-2022 | C25: 00879-2022-0-0401-JR-CI-02 | D25: Llamoja — SV de control (2021-2023) | E25: Indemnización (Contraloría) | F25: 1SC | H25: 28 | I25: dos mil veinticinco, julio cuatro | J25: 2025 | L25: Cervantes López | M25: NULA | N25: 2 | O25: 2 | AD25: DECLARADO — (evidencia en las columnas «Cita textual 1–3» de esta misma fila) | AE25: DECLARADO — (evidencia en las columnas «Cita textual 1–3» de esta misma fila) | AQ25: e) Motivación sustancialmente incongruente | AR25: b) Falta de motivación interna | AS25: Sí | AT25: «En consecuencia, es evidente el error de incongruencia incurrido por el juez A quo, al modificar o alterar el objeto de debate del proceso (fijado como primer hecho controvertido en la audiencia preliminar digitalizada a fojas cinco mil doscientos ochenta y tres); esto es, sobre el factor de atribución imputado a la parte demandada (culpa inexcusable) y la valoración jurídica efectuada en la decisión (existencia de dolo), lo que afecta el debido proceso en su vertiente al derecho a una debida motivación de las resoluciones judiciales.» | AU25: e) Incongruencia sustancial / Incongruencia procesal | AV25: «Sin perjuicio de lo señalado, del análisis de la recurrida se puede advertir también, falta de motivación interna del razonamiento empleado.» | AW25: b) Falta de motivación interna | AX25: «En consecuencia, estando a lo expuesto se concluye que la recurrida incurre en causal de nulidad prevista y sancionada en el artículo 171 concordante con el artículo 122 del Código Procesal Civil, debiendo el juez A quo emitir nueva resolución teniendo en cuenta lo señalado en la presente.» | AY25: Efecto: nulidad (arts. 171 y 122 CPC) | AZ25: La Sala cita expresamente los supuestos b) y e) de la STC 00728-2008-PHC/TC; alteró el objeto de debate (culpa inexcusable → dolo). | BA25: 879 2022 SV 2025.doc | BB25: Clasificacion_SV_ABR24_Llamoja_defectos | BC25: 1 | BD25: ABREVIADO | BE25: NULA | BF25: AN
A26: 25 | B26: 00898-2013 | C26: 00898-2013 | D26: Pre-2019 | F26: 3SC | G26: SV N° 550-2018-3SC | I26: 26/10/2018 | J26: 2018 | M26: Revocada | N26: 0 | O26: 1 | AE26: ADVERTIDO — “…obre algún punto principal o accesorio. En este caso, en la parte resolutiva de la ampulosa sentencia materia de grado, se ha omitido declarar la nulidad de los actos jurídicos contenidos en las escrituras cuya nulidad se ha demandado como pretensiones principales, no obstante haberse analizado dichos aspectos en la parte considerativa, por lo que, debe integrarse la sentencia recurrida en ese sentido.…” | AP26: Reclasificación de estatus —→ADV | BB26: Comparativa_defectos_2018_vs_2024 + Defectos_procesales_SV_CSJA | BC26: 2 | BD26: CONOCIMIENTO | BE26: REVOCADA | BF26: CR
A27: 26 | B27: 00933-2022 | C27: 00933-2022-0-0401-JR-CI-07 | D27: Llamoja — SV de control (2021-2023) | E27: Obligación de dar suma de dinero | F27: 3SC | G27: 72-2024-3SC | H27: 24 | I27: dos mil veinticuatro, Marzo ocho | J27: 2024 | L27: Burga Cervantes | M27: NULA | N27: 2 | O27: 2 | AC27: DECLARADO — (evidencia en las columnas «Cita textual 1–3» de esta misma fila) | AE27: DECLARADO — (evidencia en las columnas «Cita textual 1–3» de esta misma fila) | AP27: Migración D17→D14 | AQ27: a) Inexistencia / motivación aparente | AR27: e) Motivación sustancialmente incongruente | AS27: Sí | AT27: «Siendo así, se advierte que la sentencia objeto de apelación ha incurrido en el vicio consistente en ausencia de motivación, puesto que se ha omitido emitir pronunciamiento sobre el hecho impeditivo expuesto como defensa de fondo por el recurrente Ronald Federico Companoca Coaquira.» | AU27: a) Ausencia de motivación (etiqueta expresa) | AV27: «Ahora, de la revisión de la sentencia que viene en grado de apelación, precisamente del considerando tercero, se advierte que el Juez a quo ha omitido emitir pronunciamiento sobre el hecho impeditivo expuesto como defensa de fondo por el recurrente Ronald Federico Companoca Coaquira.» | AW27: Incongruencia omisiva: omite el hecho impeditivo | AZ27: Etiqueta expresa 'ausencia de motivación' por omitir el hecho impeditivo (defensa de fondo). Materialmente es incongruencia omisiva. SV 72-2024-3SC (menor año; existe SV 471-2025-3SC que revoca). | BA27: 933 2022 SV 2023.doc | BB27: Clasificacion_SV_ABR24_Llamoja_defectos | BC27: 1 | BD27: ABREVIADO | BE27: NULA | BF27: AN
A28: 27 | B28: 00965-2015 | C28: 00965-2015 | D28: Pre-2019 | F28: 3SC | G28: SV N° 498-2019-3SC | I28: 03/07/2019 | J28: 2019 | M28: Nula | N28: 2 | O28: 2 | U28: DECLARADO — “…e se decide u ordena, respecto de todos los puntos controvertidos, que al haberse emitido sin los requisitos señalados, se ha incurrido en causal de nulidad y que este colegiado debe sancionar en aplicación del artículo 176 del acotado Código, reponiéndose el proceso al estado de fijarse los puntos controvertidos de acuerdo a la pretensión demandada y la contestación de la demandada, dejando subsistente la in…” | AL28: DECLARADO — “…requisitos que deben contener las Resoluciones tales como los fundamentos de hecho que sustentan la decisión, y los respectivos de derecho con la cita de la norma o normas aplicables en cada punto, según el mérito de lo actuado. La expresión clara y precisa de lo que se decide u ordena, respecto de to…” | AP28: Migración D15→D23 | BB28: Comparativa_defectos_2018_vs_2024 + Defectos_procesales_SV_CSJA | BC28: 2 | BD28: CONOCIMIENTO | BE28: NULA | BF28: CN
A29: 28 | B29: 00979-2024 | C29: 00979-2024-0-0401-JR-CI-06 | D29: Matriz sumarísimos — grupo 2024 | E29: Ineficacia de acto jurídico (excepciones) | F29: 1SC | G29: Auto de Vista 960-2025-1SC | H29: Res. 26 (seis-1SC) | I29: 17/09/2025 | J29: 2025 | K29: Patricia Ruby Valdivia Franco | M29: CONFIRMADA | N29: 0 | O29: 0 | AZ29: OBSERVACIÓN DE CORPUS: es un AUTO DE VISTA sobre excepciones, no una sentencia de vista sobre el fondo. Sin vicio procesal declarado. | BB29: Matriz_defectos_procesales_1ra_SV | BC29: 1 | BD29: SUMARISIMO | BE29: CONFIRMADA | BF29: SF
A30: 29 | B30: 00992-2016 | C30: 00992-2016 | D30: Pre-2019 | F30: 3SC | G30: SV N° 76-2019-3SC | I30: 08/03/2019 | J30: 2019 | M30: Otro | N30: 2 | O30: 2 | AE30: DECLARADO — “…o 04003327. Que, la sentencia recurrida ha omitido pronunciarse sobre el fondo del asunto, señalando como presupuesto la aclaración sobre el heredero poseedor, sin analizar las declaraciones contenidas en la demanda, ya que los demandantes no tomaron conocimiento previo de estos hechos por tener domicilio en…” | AL30: DECLARADO — “…la sentencia apelada incurre en causal de nulidad prevista por el artículo 122 párrafo penúltimo concordante con el artículo 171 del Código Procesal Civil. Se deja constancia que la Sala Superior, se encuentra impedida de emitir pronunciamiento de fondo, para garantizar el dere…” | AP30: Migración D17→D16 · Migración D15→D23 | BB30: Comparativa_defectos_2018_vs_2024 + Defectos_procesales_SV_CSJA | BC30: 2 | BD30: CONOCIMIENTO | BE30: OTRO | BF30: CO
A31: 30 | B31: 01033-2023 | C31: 01033-2023-0-0401-JR-CI-04 | D31: Llamoja — SV de control (2021-2023) | E31: Indemnización (ONP) | F31: 2SC | G31: 470-2025-2SC | H31: 24 | I31: dos mil veinticinco, Setiembre treinta | J31: 2025 | L31: de la Cuba Chirinos | M31: NULA DE OFICIO | N31: 1 | O31: 1 | AE31: DECLARADO — (evidencia en las columnas «Cita textual 1–3» de esta misma fila) | AM31: Sí | AP31: Baja D13→— | AQ31: e) Motivación sustancialmente incongruente | AS31: No | AT31: «En ese sentido, existe manifiesta incongruencia entre lo que se pretendió en la demanda – responsabilidad civil contractual – y, lo que se ha resuelto en la sentencia, confundiendo ambos tipos de responsabilidad civil en su fundamento jurídico, estableciendo que el hecho objeto de probanza es la responsabilidad contractual; y, aplicando indistintamente las reglas jurídicas de ambas.» | AU31: e) Incongruencia sustancial (contractual vs. extracontractual) | AV31: «Aun cuando la nulidad procesal es de último recurso, en el caso concreto, no puede esta instancia superior superar tales vicios de motivación, pues se trata de defectos graves insubsanables.» | AW31: Efecto: nulidad de oficio, vicios insubsanables | AX31: «En consecuencia, debe declararse la nulidad de la sentencia apelada, debiendo el juez de primera instancia cumplir con determinar el tipo de responsabilidad civil en la cual nos encontramos; analizando la aplicación de principios para sustanciar de modo correcto la pretensión del actor en los hechos y fundamento jurídico invocado.» | AY31: Alcance del reenvío: determinar el tipo de responsabilidad | AZ31: 'Manifiesta incongruencia' entre lo pretendido (resp. contractual) y lo resuelto; confusión de regímenes de responsabilidad. | BA31: 1033 2023 SV.doc | BB31: Clasificacion_SV_ABR24_Llamoja_defectos | BC31: 1 | BD31: ABREVIADO | BE31: NULA | BF31: AN
A32: 31 | B32: 01101-2022 | C32: 01101-2022 | D32: 2024 | F32: 2SC | G32: SV N° 226-2025-2SC | I32: 16/05/2025 | J32: 2025 | M32: Nula | N32: 1 | O32: 1 | AL32: DECLARADO — “…lo no es posible particularmente en este caso, debido a que el error en la motivación de la recurrida, contraviene de esta manera no sólo lo establecido en el numeral 3) del artículo 122 del T.U.O. del Código Procesal Civil, sino también lo dispuesto en el numeral 5) del artículo 139 de nuestra Constitución Política, po…” | AP32: Migración D15→D23 | BB32: Comparativa_defectos_2018_vs_2024 + Defectos_procesales_SV_CSJA | BC32: 2 | BD32: CONOCIMIENTO | BE32: NULA | BF32: CN
A33: 32 | B33: 01286-2022 | C33: 01286-2022 | D33: 2024 | F33: 2SC | G33: SV N° 341-2025-2SC | I33: 18/07/2025 | J33: 2025 | M33: Nula e insubsistente | N33: 2 | O33: 3 | P33: DECLARADO — “…ntencia fue expedida incumpliendo el inciso 3) del artículo 139º de la Constitución Política del Estado, en concordancia con el artículo I del título preliminar del código procesal civil y el artículo 165º del código procesal civil, ya que todas las notificaciones se han efectuado en un domicilio que no es el suyo. 4.4. Al respecto,…” | Q33: DERIVADO — “…esales posteriores, incluida la sentencia. En consecuencia, se vulneró su derecho de defensa y contradicción, configurándose así una infracción al debido proceso. Este vicio procesal resulta ser insubsanable, al haber impedido l…” | S33: DECLARADO — “…tubre de dos mil veintidós [ver de fojas 337 a 339 del eje] se declara rebelde al recurrente Rossvel Gregorio Mamani Chire, además se indica, que debe notificársele con arreglo a lo dispuesto por el artículo 459º del código procesal civil. Asimismo, la mencionada resolución fue notificada al…” | AM33: Sí | AO33: D04: la cita registrada es narrativa (refiere la declaración de rebeldía y el art. 459 CPC) y no contiene juicio sobre su invalidez. Sustituir por el pasaje que anula los actos desde la Res. N° 04. | AP33: Baja D08→— · Baja D20→— · Reclasificación de estatus D02→D02 (derivado) | BB33: Comparativa_defectos_2018_vs_2024 + Defectos_procesales_SV_CSJA | BC33: 2 | BD33: CONOCIMIENTO | BE33: NULA | BF33: CN
A34: 33 | B34: 01328-2023 | C34: 01328-2023 | D34: 2024 | F34: 2SC | G34: SV N° 155-2025-2SC | I34: 08/04/2025 | J34: 2025 | M34: Revocada | N34: 0 | O34: 0 | BB34: Comparativa_defectos_2018_vs_2024 + Defectos_procesales_SV_CSJA | BC34: 2 | BD34: CONOCIMIENTO | BE34: REVOCADA | BF34: CR
A35: 34 | B35: 01376-2023 | C35: 01376-2023 | D35: 2024 | F35: 2SC | G35: SV N° 033-2026-2SC | I35: 23/01/2026 | J35: 2026 | M35: Revocada | N35: 2 | O35: 2 | AA35: DECLARADO — “…rente que la jueza de primera instancia incurre en omisión en cuanto a la valoración conjunta y razonada de los medios probatorios admitidos de la parte demandante y en consecuencia se ha constituido un vicio in procedendo debido que todos los medios probatorios admitidos por la jueza de primera instancia deben ser valorados en forma conjunta o en…” | AH35: DECLARADO — “…ción N° 07 de fecha tres de noviembre de dos mil veintitrés [ver fojas 232 y 233 del EJE], en donde se declaró improcedente tanto la contestación de la demanda como la reconvención por extemporánea en relación al condemandado Alfredo Joaquín Flores Apaza y disponiendo que el juzgado de primera instancia proceda a calificar la contestación de la demanda y…” | AO35: La cita registrada en D20 es literalmente idéntica a la CITA1 del expediente 04965-2023. Verificar en el original antes de conservar el registro. | AP35: Migración D11→D12 · Migración D08→D19 · Baja D20→— | BB35: Comparativa_defectos_2018_vs_2024 + Defectos_procesales_SV_CSJA | BC35: 2 | BD35: CONOCIMIENTO | BE35: REVOCADA | BF35: CR
A36: 35 | B36: 01417-2017 | C36: 01417-2017 | D36: Pre-2019 | F36: 2SC | G36: SV N° 004-2020-2SC | I36: 03/01/2020 | J36: 2020 | M36: Nula | N36: 1 | O36: 1 | AL36: DECLARADO — “…en mérito a lo expuesto precedentemente se concluye que la sentencia recurrida no se encuentra debidamente motivada, contraviniendo de esta manera lo establecido en el segundo párrafo del artículo 122 del Código Procesal Civil, por lo que, corresponde declarar la nulidad de la apelada, de conformidad con el artículo 171 del Código Procesal acotado. PARTE RESOLUTIVA: Fundamentos…” | AP36: Migración D15→D23 | BB36: Comparativa_defectos_2018_vs_2024 + Defectos_procesales_SV_CSJA | BC36: 2 | BD36: CONOCIMIENTO | BE36: NULA | BF36: CN
A37: 36 | B37: 01535-2022 | C37: 01535-2022 | D37: 2024 | F37: 2SC | G37: SV N° 572-2024-2SC | I37: 11/12/2024 | J37: 2024 | M37: Nula | N37: 2 | O37: 2 | Z37: DECLARADO — “…n apelada no se ha dado una respuesta debidamente razonada al justiciable, pues se ha omitido valorar los argumentos expuestos por la parte apelante, así como los medios probatorios adjuntos al escrito de solicitud de medida cautelar, existiendo una motivación aparente, la cual es entendida por el Tribunal Constitucional como…” | AC37: DECLARADO — “…a que a través de la resolución apelada no se ha dado una respuesta debidamente razonada al justiciable, pues se ha omitido valorar los argumentos expuestos por la parte apelante, así como los medios probatorios adjuntos al escrito de solicitud de medida cautelar…” | AP37: Migración D15→D14 | BB37: Comparativa_defectos_2018_vs_2024 + Defectos_procesales_SV_CSJA | BC37: 2 | BD37: CONOCIMIENTO | BE37: NULA | BF37: CN
A38: 37 | B38: 01549-2017 | C38: 01549-2017-0-0401-JR-CI-04 | D38: Matriz sumarísimos — anteriores a 2019 | E38: Otorgamiento de escritura pública | F38: 2SC | G38: SV 173-2019-2SC | H38: Res. 18 (tres-2SC) | I38: 10/05/2019 | J38: 2019 | K38: Justo Quispe Apaza | M38: REVOCADA → IMPROCEDENTE | N38: 0 | O38: 0 | AZ38: Sin vicio procesal declarado. La revocatoria se funda en error de derecho sustantivo (condición suspensiva no acreditada; IX Pleno Casatorio). | BB38: Matriz_defectos_procesales_1ra_SV | BC38: 1 | BD38: SUMARISIMO | BE38: REVOCADA | BF38: SR
A39: 38 | B39: 01647-2019 | C39: 01647-2019 | D39: 2024 | F39: 2SC | G39: SV N° 082-2026-2SC | I39: 18/03/2026 | J39: 2026 | M39: Nula | N39: 2 | O39: 2 | AA39: DECLARADO — “…uye, que al haberse expedido la sentencia materia de grado, sin que se haya realizado un análisis conjunto y razonado de los medios probatorios admitidos y actuados en el proceso como lo dispone el artículo 197 del Código Procesal Civil, se ha vulnerado el principio al debido proceso y el de motivación establecido en los incisos 3° y 5° del artículo 139 de nues…” | AC39: DECLARADO — “…al debido proceso y el de motivación establecido en los incisos 3° y 5° del artículo 139 de nuestra constitución; pues nos encontramos ante una motivación aparente; por lo que, en aplicación de lo dispuesto por el artículo 176, concordante con el 171 del Código Procesal Civil debe d…” | AP39: Migración D11→D12 | BB39: Comparativa_defectos_2018_vs_2024 + Defectos_procesales_SV_CSJA | BC39: 2 | BD39: CONOCIMIENTO | BE39: NULA | BF39: CN
A40: 39 | B40: 01650-2023 | C40: 01650-2023 | D40: 2024 | G40: SV N° 267-2025 | I40: 30/06/2025 | J40: 2025 | M40: Revocada | N40: 0 | O40: 0 | BB40: Comparativa_defectos_2018_vs_2024 + Defectos_procesales_SV_CSJA | BC40: 2 | BD40: CONOCIMIENTO | BE40: REVOCADA | BF40: CR
...

Sheet Marcas_declaradas
A1: Solo registros DECLARADOS por la Sala como fundamento de la decisión (ratio). Es la base de conteo recomendada para la tesis.
A2: N° | B2: Clave expediente | C2: Corpus / grupo | D2: Año SV | E2: Sala | F2: D01 | G2: D02 | H2: D03 | I2: D04 | J2: D05 | K2: D06 | L2: D07 | M2: D08 | N2: D09 | O2: D10 | P2: D11 | Q2: D12 | R2: D13 | S2: D14 | T2: D15 | U2: D16 | V2: D17 | W2: D18 | X2: D19 | Y2: D20 | Z2: D21 | AA2: D22 | AB2: D23 | AC2: Total
A3: 1 | B3: 00001-2018 | C3: Matriz sumarísimos — anteriores a 2019 | D3: 2019 | E3: 2SC | F3: 0 | G3: 0 | H3: 0 | I3: 0 | J3: 0 | K3: 0 | L3: 0 | M3: 0 | N3: 0 | O3: 0 | P3: 0 | Q3: 1 | R3: 0 | S3: 0 | T3: 1 | U3: 0 | V3: 0 | W3: 0 | X3: 0 | Y3: 0 | Z3: 0 | AA3: 0 | AB3: 0 | AC3: 2
A4: 2 | B4: 00072-2023 | C4: Matriz sumarísimos — grupo 2024 | D4: 2025 | E4: 2SC | F4: 0 | G4: 0 | H4: 0 | I4: 0 | J4: 0 | K4: 0 | L4: 0 | M4: 0 | N4: 0 | O4: 0 | P4: 1 | Q4: 0 | R4: 0 | S4: 0 | T4: 1 | U4: 1 | V4: 0 | W4: 0 | X4: 0 | Y4: 0 | Z4: 1 | AA4: 0 | AB4: 0 | AC4: 4
A5: 3 | B5: 00115-2012 | C5: Matriz sumarísimos — anteriores a 2019 | D5: 2018 | E5: 2SC | F5: 1 | G5: 0 | H5: 0 | I5: 0 | J5: 0 | K5: 0 | L5: 0 | M5: 0 | N5: 0 | O5: 0 | P5: 0 | Q5: 0 | R5: 0 | S5: 0 | T5: 0 | U5: 0 | V5: 0 | W5: 0 | X5: 0 | Y5: 0 | Z5: 0 | AA5: 0 | AB5: 0 | AC5: 1
A6: 4 | B6: 00129-2022 | C6: Matriz sumarísimos — grupo 2024 | D6: 2024 | E6: 2SC | F6: 0 | G6: 0 | H6: 0 | I6: 0 | J6: 0 | K6: 0 | L6: 0 | M6: 0 | N6: 0 | O6: 0 | P6: 0 | Q6: 0 | R6: 0 | S6: 0 | T6: 0 | U6: 0 | V6: 0 | W6: 0 | X6: 0 | Y6: 0 | Z6: 0 | AA6: 0 | AB6: 0 | AC6: 0
A7: 5 | B7: 00132-2015 | C7: Pre-2019 | D7: 2018 | E7: 2SC | F7: 0 | G7: 0 | H7: 0 | I7: 0 | J7: 0 | K7: 0 | L7: 0 | M7: 0 | N7: 0 | O7: 0 | P7: 0 | Q7: 0 | R7: 0 | S7: 0 | T7: 0 | U7: 0 | V7: 0 | W7: 0 | X7: 0 | Y7: 0 | Z7: 0 | AA7: 0 | AB7: 0 | AC7: 0
A8: 6 | B8: 00153-2022 | C8: Matriz sumarísimos — grupo 2024 | D8: 2025 | E8: 3SC | F8: 0 | G8: 0 | H8: 0 | I8: 0 | J8: 0 | K8: 0 | L8: 0 | M8: 0 | N8: 0 | O8: 0 | P8: 0 | Q8: 0 | R8: 0 | S8: 0 | T8: 0 | U8: 0 | V8: 0 | W8: 0 | X8: 0 | Y8: 0 | Z8: 0 | AA8: 0 | AB8: 0 | AC8: 0
A9: 7 | B9: 00192-2021 | C9: 2024 | D9: 2026 | F9: 0 | G9: 0 | H9: 0 | I9: 0 | J9: 0 | K9: 0 | L9: 0 | M9: 0 | N9: 0 | O9: 0 | P9: 0 | Q9: 0 | R9: 0 | S9: 0 | T9: 0 | U9: 0 | V9: 0 | W9: 0 | X9: 0 | Y9: 0 | Z9: 0 | AA9: 0 | AB9: 0 | AC9: 0
A10: 8 | B10: 00234-2018 | C10: Matriz sumarísimos — anteriores a 2019 | D10: 2019 | E10: 3SC | F10: 0 | G10: 0 | H10: 0 | I10: 0 | J10: 0 | K10: 0 | L10: 0 | M10: 0 | N10: 0 | O10: 0 | P10: 0 | Q10: 0 | R10: 0 | S10: 0 | T10: 0 | U10: 0 | V10: 0 | W10: 0 | X10: 0 | Y10: 0 | Z10: 0 | AA10: 0 | AB10: 0 | AC10: 0
A11: 9 | B11: 00320-2023 | C11: 2024 | D11: 2025 | E11: 2SC | F11: 0 | G11: 0 | H11: 0 | I11: 0 | J11: 0 | K11: 0 | L11: 0 | M11: 0 | N11: 0 | O11: 0 | P11: 0 | Q11: 0 | R11: 1 | S11: 0 | T11: 0 | U11: 0 | V11: 0 | W11: 0 | X11: 0 | Y11: 0 | Z11: 0 | AA11: 0 | AB11: 0 | AC11: 1
A12: 10 | B12: 00340-2002 | C12: Pre-2019 | D12: 2018 | E12: 2SC | F12: 0 | G12: 1 | H12: 0 | I12: 0 | J12: 0 | K12: 0 | L12: 0 | M12: 0 | N12: 0 | O12: 0 | P12: 0 | Q12: 0 | R12: 0 | S12: 0 | T12: 0 | U12: 1 | V12: 0 | W12: 0 | X12: 0 | Y12: 0 | Z12: 0 | AA12: 0 | AB12: 0 | AC12: 2
A13: 11 | B13: 00367-2024 | C13: Matriz sumarísimos — grupo 2024 | D13: 2024 | E13: 1SC | F13: 0 | G13: 0 | H13: 0 | I13: 0 | J13: 0 | K13: 0 | L13: 0 | M13: 0 | N13: 0 | O13: 0 | P13: 0 | Q13: 0 | R13: 0 | S13: 0 | T13: 0 | U13: 0 | V13: 0 | W13: 0 | X13: 0 | Y13: 0 | Z13: 0 | AA13: 0 | AB13: 0 | AC13: 0
A14: 12 | B14: 00414-2023 | C14: Llamoja — SV de control (2021-2023) | D14: 2025 | E14: 3SC | F14: 0 | G14: 0 | H14: 0 | I14: 0 | J14: 0 | K14: 0 | L14: 0 | M14: 0 | N14: 0 | O14: 0 | P14: 0 | Q14: 0 | R14: 1 | S14: 0 | T14: 0 | U14: 1 | V14: 0 | W14: 0 | X14: 0 | Y14: 0 | Z14: 0 | AA14: 0 | AB14: 0 | AC14: 2
A15: 13 | B15: 00428-2017 | C15: Matriz sumarísimos — anteriores a 2019 | D15: 2020 | E15: 2SC | F15: 0 | G15: 0 | H15: 0 | I15: 0 | J15: 0 | K15: 0 | L15: 0 | M15: 0 | N15: 0 | O15: 0 | P15: 0 | Q15: 0 | R15: 0 | S15: 0 | T15: 0 | U15: 0 | V15: 0 | W15: 0 | X15: 0 | Y15: 0 | Z15: 0 | AA15: 0 | AB15: 0 | AC15: 0
A16: 14 | B16: 00598-2022 | C16: 2024 | D16: 2025 | E16: 3SC | F16: 0 | G16: 0 | H16: 0 | I16: 0 | J16: 0 | K16: 0 | L16: 0 | M16: 0 | N16: 0 | O16: 0 | P16: 0 | Q16: 1 | R16: 1 | S16: 0 | T16: 0 | U16: 0 | V16: 0 | W16: 0 | X16: 0 | Y16: 0 | Z16: 0 | AA16: 0 | AB16: 0 | AC16: 2
A17: 15 | B17: 00646-2024 | C17: Matriz sumarísimos — grupo 2024 | D17: 2025 | E17: 2SC | F17: 0 | G17: 0 | H17: 0 | I17: 0 | J17: 0 | K17: 0 | L17: 0 | M17: 0 | N17: 0 | O17: 0 | P17: 0 | Q17: 1 | R17: 0 | S17: 0 | T17: 0 | U17: 1 | V17: 0 | W17: 0 | X17: 0 | Y17: 0 | Z17: 0 | AA17: 0 | AB17: 1 | AC17: 3
A18: 16 | B18: 00661-2023 | C18: Matriz sumarísimos — grupo 2024 | D18: 2025 | E18: 2SC | F18: 0 | G18: 0 | H18: 0 | I18: 0 | J18: 0 | K18: 0 | L18: 0 | M18: 0 | N18: 0 | O18: 0 | P18: 0 | Q18: 1 | R18: 1 | S18: 0 | T18: 0 | U18: 0 | V18: 0 | W18: 0 | X18: 0 | Y18: 0 | Z18: 0 | AA18: 0 | AB18: 0 | AC18: 2
A19: 17 | B19: 00742-2022 | C19: 2024 | D19: 2025 | F19: 0 | G19: 1 | H19: 0 | I19: 1 | J19: 0 | K19: 0 | L19: 0 | M19: 0 | N19: 0 | O19: 0 | P19: 1 | Q19: 0 | R19: 0 | S19: 0 | T19: 0 | U19: 1 | V19: 0 | W19: 0 | X19: 0 | Y19: 0 | Z19: 0 | AA19: 0 | AB19: 0 | AC19: 4
A20: 18 | B20: 00748-2013 | C20: Pre-2019 | D20: 2018 | E20: 2SC | F20: 0 | G20: 0 | H20: 0 | I20: 0 | J20: 0 | K20: 0 | L20: 0 | M20: 0 | N20: 0 | O20: 0 | P20: 0 | Q20: 0 | R20: 0 | S20: 0 | T20: 1 | U20: 0 | V20: 0 | W20: 0 | X20: 0 | Y20: 0 | Z20: 0 | AA20: 0 | AB20: 0 | AC20: 1
A21: 19 | B21: 00760-2021 | C21: Llamoja — SV de control (2021-2023) | D21: 2025 | E21: 3SC | F21: 0 | G21: 0 | H21: 0 | I21: 0 | J21: 0 | K21: 0 | L21: 0 | M21: 1 | N21: 0 | O21: 1 | P21: 0 | Q21: 0 | R21: 0 | S21: 0 | T21: 0 | U21: 0 | V21: 0 | W21: 0 | X21: 0 | Y21: 0 | Z21: 0 | AA21: 0 | AB21: 0 | AC21: 2
A22: 20 | B22: 00774-2021 | C22: Llamoja — SV de control (2021-2023) | D22: 2025 | E22: 2SC | F22: 0 | G22: 0 | H22: 0 | I22: 0 | J22: 0 | K22: 0 | L22: 0 | M22: 0 | N22: 0 | O22: 0 | P22: 0 | Q22: 0 | R22: 0 | S22: 0 | T22: 0 | U22: 1 | V22: 0 | W22: 0 | X22: 0 | Y22: 0 | Z22: 1 | AA22: 0 | AB22: 0 | AC22: 2
A23: 21 | B23: 00788-2013 | C23: Pre-2019 | D23: 2021 | E23: 2SC | F23: 0 | G23: 0 | H23: 0 | I23: 0 | J23: 0 | K23: 0 | L23: 0 | M23: 0 | N23: 0 | O23: 0 | P23: 0 | Q23: 0 | R23: 0 | S23: 0 | T23: 0 | U23: 1 | V23: 0 | W23: 0 | X23: 0 | Y23: 0 | Z23: 0 | AA23: 0 | AB23: 0 | AC23: 1
A24: 22 | B24: 00848-2011 | C24: Matriz sumarísimos — anteriores a 2019 | D24: 2019 | E24: 3SC | F24: 0 | G24: 0 | H24: 0 | I24: 0 | J24: 0 | K24: 0 | L24: 0 | M24: 0 | N24: 0 | O24: 0 | P24: 0 | Q24: 0 | R24: 0 | S24: 0 | T24: 0 | U24: 0 | V24: 0 | W24: 0 | X24: 0 | Y24: 0 | Z24: 0 | AA24: 0 | AB24: 0 | AC24: 0
A25: 23 | B25: 00856-2017 | C25: Pre-2019 | D25: 2019 | E25: 1SC | F25: 0 | G25: 0 | H25: 0 | I25: 0 | J25: 0 | K25: 0 | L25: 0 | M25: 0 | N25: 0 | O25: 0 | P25: 0 | Q25: 0 | R25: 0 | S25: 0 | T25: 0 | U25: 1 | V25: 0 | W25: 0 | X25: 0 | Y25: 0 | Z25: 0 | AA25: 0 | AB25: 0 | AC25: 1
A26: 24 | B26: 00879-2022 | C26: Llamoja — SV de control (2021-2023) | D26: 2025 | E26: 1SC | F26: 0 | G26: 0 | H26: 0 | I26: 0 | J26: 0 | K26: 0 | L26: 0 | M26: 0 | N26: 0 | O26: 0 | P26: 0 | Q26: 0 | R26: 0 | S26: 0 | T26: 1 | U26: 1 | V26: 0 | W26: 0 | X26: 0 | Y26: 0 | Z26: 0 | AA26: 0 | AB26: 0 | AC26: 2
A27: 25 | B27: 00898-2013 | C27: Pre-2019 | D27: 2018 | E27: 3SC | F27: 0 | G27: 0 | H27: 0 | I27: 0 | J27: 0 | K27: 0 | L27: 0 | M27: 0 | N27: 0 | O27: 0 | P27: 0 | Q27: 0 | R27: 0 | S27: 0 | T27: 0 | U27: 0 | V27: 0 | W27: 0 | X27: 0 | Y27: 0 | Z27: 0 | AA27: 0 | AB27: 0 | AC27: 0
A28: 26 | B28: 00933-2022 | C28: Llamoja — SV de control (2021-2023) | D28: 2024 | E28: 3SC | F28: 0 | G28: 0 | H28: 0 | I28: 0 | J28: 0 | K28: 0 | L28: 0 | M28: 0 | N28: 0 | O28: 0 | P28: 0 | Q28: 0 | R28: 0 | S28: 1 | T28: 0 | U28: 1 | V28: 0 | W28: 0 | X28: 0 | Y28: 0 | Z28: 0 | AA28: 0 | AB28: 0 | AC28: 2
A29: 27 | B29: 00965-2015 | C29: Pre-2019 | D29: 2019 | E29: 3SC | F29: 0 | G29: 0 | H29: 0 | I29: 0 | J29: 0 | K29: 1 | L29: 0 | M29: 0 | N29: 0 | O29: 0 | P29: 0 | Q29: 0 | R29: 0 | S29: 0 | T29: 0 | U29: 0 | V29: 0 | W29: 0 | X29: 0 | Y29: 0 | Z29: 0 | AA29: 0 | AB29: 1 | AC29: 2
A30: 28 | B30: 00979-2024 | C30: Matriz sumarísimos — grupo 2024 | D30: 2025 | E30: 1SC | F30: 0 | G30: 0 | H30: 0 | I30: 0 | J30: 0 | K30: 0 | L30: 0 | M30: 0 | N30: 0 | O30: 0 | P30: 0 | Q30: 0 | R30: 0 | S30: 0 | T30: 0 | U30: 0 | V30: 0 | W30: 0 | X30: 0 | Y30: 0 | Z30: 0 | AA30: 0 | AB30: 0 | AC30: 0
A31: 29 | B31: 00992-2016 | C31: Pre-2019 | D31: 2019 | E31: 3SC | F31: 0 | G31: 0 | H31: 0 | I31: 0 | J31: 0 | K31: 0 | L31: 0 | M31: 0 | N31: 0 | O31: 0 | P31: 0 | Q31: 0 | R31: 0 | S31: 0 | T31: 0 | U31: 1 | V31: 0 | W31: 0 | X31: 0 | Y31: 0 | Z31: 0 | AA31: 0 | AB31: 1 | AC31: 2
... A40: 38 | B40: 01647-2019 | C40: 2024 | D40: 2026 | E40: 2SC | F40: 0 | G40: 0 | H40: 0 | I40: 0 | J40: 0 | K40: 0 | L40: 0 | M40: 0 | N40: 0 | O40: 0 | P40: 0 | Q40: 1 | R40: 0 | S40: 1 | T40: 0 | U40: 0 | V40: 0 | W40: 0 | X40: 0 | Y40: 0 | Z40: 0 | AA40: 0 | AB40: 0 | AC40: 2
A41: 39 | B41: 01650-2023 | C41: 2024 | D41: 2025 | F41: 0 | G41: 0 | H41: 0 | I41: 0 | J41: 0 | K41: 0 | L41: 0 | M41: 0 | N41: 0 | O41: 0 | P41: 0 | Q41: 0 | R41: 0 | S41: 0 | T41: 0 | U41: 0 | V41: 0 | W41: 0 | X41: 0 | Y41: 0 | Z41: 0 | AA41: 0 | AB41: 0 | AC41: 0
A42: 40 | B42: 01681-2023 | C42: Llamoja — SV de control (2021-2023) | D42: 2025 | E42: 3SC | F42: 0 | G42: 0 | H42: 0 | I42: 0 | J42: 0 | K42: 1 | L42: 0 | M42: 0 | N42: 0 | O42: 0 | P42: 0 | Q42: 0 | R42: 0 | S42: 0 | T42: 1 | U42: 0 | V42: 0 | W42: 0 | X42: 0 | Y42: 0 | Z42: 0 | AA42: 0 | AB42: 0 | AC42: 2
A43: 41 | B43: 01723-2022 | C43: Llamoja — SV de control (2021-2023) | D43: 2025 | E43: 2SC | F43: 0 | G43: 0 | H43: 0 | I43: 0 | J43: 0 | K43: 0 | L43: 0 | M43: 0 | N43: 0 | O43: 0 | P43: 0 | Q43: 0 | R43: 0 | S43: 0 | T43: 0 | U43: 0 | V43: 0 | W43: 0 | X43: 0 | Y43: 0 | Z43: 0 | AA43: 0 | AB43: 0 | AC43: 0
A44: 42 | B44: 01734-2017 | C44: Pre-2019 | D44: 2019 | E44: 2SC | F44: 0 | G44: 0 | H44: 0 | I44: 0 | J44: 0 | K44: 0 | L44: 0 | M44: 0 | N44: 0 | O44: 0 | P44: 0 | Q44: 0 | R44: 0 | S44: 0 | T44: 1 | U44: 0 | V44: 0 | W44: 0 | X44: 0 | Y44: 0 | Z44: 0 | AA44: 0 | AB44: 0 | AC44: 1
A45: 43 | B45: 01835-2024 | C45: 2024 | D45: 2025 | E45: 1SC | F45: 0 | G45: 0 | H45: 0 | I45: 0 | J45: 0 | K45: 0 | L45: 0 | M45: 0 | N45: 0 | O45: 0 | P45: 0 | Q45: 0 | R45: 0 | S45: 0 | T45: 0 | U45: 0 | V45: 0 | W45: 0 | X45: 0 | Y45: 0 | Z45: 0 | AA45: 0 | AB45: 0 | AC45: 0
A46: 44 | B46: 01869-2023 | C46: Llamoja — SV de control (2021-2023) | D46: 2026 | E46: 2SC | F46: 0 | G46: 0 | H46: 0 | I46: 0 | J46: 0 | K46: 0 | L46: 0 | M46: 0 | N46: 0 | O46: 0 | P46: 0 | Q46: 1 | R46: 1 | S46: 0 | T46: 0 | U46: 0 | V46: 0 | W46: 0 | X46: 0 | Y46: 0 | Z46: 1 | AA46: 0 | AB46: 0 | AC46: 3
A47: 45 | B47: 01879-2022 | C47: 2024 | D47: 2025 | E47: 2SC | F47: 0 | G47: 0 | H47: 0 | I47: 0 | J47: 0 | K47: 0 | L47: 0 | M47: 0 | N47: 0 | O47: 0 | P47: 0 | Q47: 0 | R47: 0 | S47: 0 | T47: 0 | U47: 0 | V47: 0 | W47: 0 | X47: 0 | Y47: 0 | Z47: 0 | AA47: 0 | AB47: 1 | AC47: 1
A48: 46 | B48: 01888-2011 | C48: Pre-2019 | D48: 2020 | E48: 2SC | F48: 0 | G48: 0 | H48: 0 | I48: 0 | J48: 0 | K48: 0 | L48: 0 | M48: 0 | N48: 0 | O48: 0 | P48: 0 | Q48: 0 | R48: 0 | S48: 0 | T48: 0 | U48: 0 | V48: 0 | W48: 0 | X48: 1 | Y48: 0 | Z48: 0 | AA48: 0 | AB48: 0 | AC48: 1
...

Sheet Marcas_todas
A1: Todos los registros, cualquiera sea su estatus (declarado, derivado, alegado, voto en minoría, advertido). Úsese solo para rastreo, no para frecuencias.
A2: N° | B2: Clave expediente | C2: Corpus / grupo | D2: Año SV | E2: Sala | F2: D01 | G2: D02 | H2: D03 | I2: D04 | J2: D05 | K2: D06 | L2: D07 | M2: D08 | N2: D09 | O2: D10 | P2: D11 | Q2: D12 | R2: D13 | S2: D14 | T2: D15 | U2: D16 | V2: D17 | W2: D18 | X2: D19 | Y2: D20 | Z2: D21 | AA2: D22 | AB2: D23 | AC2: Total
A3: 1 | B3: 00001-2018 | C3: Matriz sumarísimos — anteriores a 2019 | D3: 2019 | E3: 2SC | F3: 0 | G3: 0 | H3: 0 | I3: 0 | J3: 0 | K3: 0 | L3: 0 | M3: 0 | N3: 0 | O3: 0 | P3: 0 | Q3: 1 | R3: 0 | S3: 0 | T3: 1 | U3: 0 | V3: 0 | W3: 0 | X3: 0 | Y3: 0 | Z3: 0 | AA3: 0 | AB3: 0 | AC3: 2
A4: 2 | B4: 00072-2023 | C4: Matriz sumarísimos — grupo 2024 | D4: 2025 | E4: 2SC | F4: 0 | G4: 0 | H4: 0 | I4: 0 | J4: 0 | K4: 0 | L4: 0 | M4: 0 | N4: 0 | O4: 0 | P4: 1 | Q4: 0 | R4: 0 | S4: 0 | T4: 1 | U4: 1 | V4: 0 | W4: 0 | X4: 0 | Y4: 0 | Z4: 1 | AA4: 0 | AB4: 0 | AC4: 4
A5: 3 | B5: 00115-2012 | C5: Matriz sumarísimos — anteriores a 2019 | D5: 2018 | E5: 2SC | F5: 1 | G5: 1 | H5: 0 | I5: 0 | J5: 0 | K5: 0 | L5: 0 | M5: 0 | N5: 0 | O5: 0 | P5: 0 | Q5: 0 | R5: 0 | S5: 0 | T5: 0 | U5: 0 | V5: 0 | W5: 0 | X5: 0 | Y5: 0 | Z5: 0 | AA5: 0 | AB5: 0 | AC5: 2
A6: 4 | B6: 00129-2022 | C6: Matriz sumarísimos — grupo 2024 | D6: 2024 | E6: 2SC | F6: 0 | G6: 0 | H6: 0 | I6: 0 | J6: 0 | K6: 0 | L6: 0 | M6: 0 | N6: 0 | O6: 0 | P6: 0 | Q6: 0 | R6: 0 | S6: 0 | T6: 0 | U6: 0 | V6: 0 | W6: 0 | X6: 0 | Y6: 0 | Z6: 0 | AA6: 0 | AB6: 0 | AC6: 0
A7: 5 | B7: 00132-2015 | C7: Pre-2019 | D7: 2018 | E7: 2SC | F7: 0 | G7: 0 | H7: 0 | I7: 0 | J7: 0 | K7: 0 | L7: 0 | M7: 0 | N7: 0 | O7: 0 | P7: 0 | Q7: 0 | R7: 0 | S7: 0 | T7: 0 | U7: 0 | V7: 0 | W7: 0 | X7: 0 | Y7: 0 | Z7: 0 | AA7: 0 | AB7: 0 | AC7: 0
A8: 6 | B8: 00153-2022 | C8: Matriz sumarísimos — grupo 2024 | D8: 2025 | E8: 3SC | F8: 0 | G8: 0 | H8: 0 | I8: 0 | J8: 0 | K8: 0 | L8: 0 | M8: 0 | N8: 0 | O8: 0 | P8: 0 | Q8: 0 | R8: 0 | S8: 0 | T8: 0 | U8: 0 | V8: 0 | W8: 0 | X8: 0 | Y8: 0 | Z8: 0 | AA8: 0 | AB8: 0 | AC8: 0
A9: 7 | B9: 00192-2021 | C9: 2024 | D9: 2026 | F9: 0 | G9: 0 | H9: 0 | I9: 0 | J9: 0 | K9: 0 | L9: 0 | M9: 0 | N9: 0 | O9: 0 | P9: 0 | Q9: 0 | R9: 0 | S9: 0 | T9: 0 | U9: 0 | V9: 0 | W9: 0 | X9: 0 | Y9: 0 | Z9: 0 | AA9: 0 | AB9: 0 | AC9: 0
A10: 8 | B10: 00234-2018 | C10: Matriz sumarísimos — anteriores a 2019 | D10: 2019 | E10: 3SC | F10: 0 | G10: 0 | H10: 0 | I10: 0 | J10: 0 | K10: 0 | L10: 0 | M10: 0 | N10: 0 | O10: 0 | P10: 0 | Q10: 0 | R10: 0 | S10: 0 | T10: 0 | U10: 0 | V10: 0 | W10: 0 | X10: 1 | Y10: 0 | Z10: 0 | AA10: 0 | AB10: 0 | AC10: 1
A11: 9 | B11: 00320-2023 | C11: 2024 | D11: 2025 | E11: 2SC | F11: 0 | G11: 0 | H11: 0 | I11: 0 | J11: 0 | K11: 0 | L11: 0 | M11: 0 | N11: 0 | O11: 0 | P11: 0 | Q11: 0 | R11: 1 | S11: 0 | T11: 0 | U11: 0 | V11: 0 | W11: 0 | X11: 0 | Y11: 0 | Z11: 0 | AA11: 0 | AB11: 0 | AC11: 1
A12: 10 | B12: 00340-2002 | C12: Pre-2019 | D12: 2018 | E12: 2SC | F12: 0 | G12: 1 | H12: 0 | I12: 0 | J12: 0 | K12: 0 | L12: 0 | M12: 0 | N12: 0 | O12: 0 | P12: 0 | Q12: 0 | R12: 0 | S12: 0 | T12: 0 | U12: 1 | V12: 0 | W12: 0 | X12: 0 | Y12: 0 | Z12: 0 | AA12: 0 | AB12: 0 | AC12: 2
A13: 11 | B13: 00367-2024 | C13: Matriz sumarísimos — grupo 2024 | D13: 2024 | E13: 1SC | F13: 0 | G13: 0 | H13: 0 | I13: 0 | J13: 0 | K13: 0 | L13: 0 | M13: 0 | N13: 0 | O13: 0 | P13: 0 | Q13: 0 | R13: 0 | S13: 0 | T13: 0 | U13: 0 | V13: 0 | W13: 0 | X13: 0 | Y13: 0 | Z13: 0 | AA13: 0 | AB13: 0 | AC13: 0
A14: 12 | B14: 00414-2023 | C14: Llamoja — SV de control (2021-2023) | D14: 2025 | E14: 3SC | F14: 0 | G14: 0 | H14: 0 | I14: 0 | J14: 0 | K14: 0 | L14: 0 | M14: 0 | N14: 0 | O14: 0 | P14: 0 | Q14: 0 | R14: 1 | S14: 0 | T14: 0 | U14: 1 | V14: 0 | W14: 0 | X14: 0 | Y14: 0 | Z14: 0 | AA14: 0 | AB14: 0 | AC14: 2
